[2025-03-05T22:19:31.050+0000] {taskinstance.py:1956} INFO - Dependencies all met for dep_context=non-requeueable deps ti=<TaskInstance: mercadolibre_técnica.email_alert_task manual__2025-03-05T22:19:26.784773+00:00 [queued]>
[2025-03-05T22:19:31.059+0000] {taskinstance.py:1956} INFO - Dependencies all met for dep_context=requeueable deps ti=<TaskInstance: mercadolibre_técnica.email_alert_task manual__2025-03-05T22:19:26.784773+00:00 [queued]>
[2025-03-05T22:19:31.060+0000] {taskinstance.py:2170} INFO - Starting attempt 1 of 1
[2025-03-05T22:19:31.074+0000] {taskinstance.py:2191} INFO - Executing <Task(PythonOperator): email_alert_task> on 2025-03-05 22:19:26.784773+00:00
[2025-03-05T22:19:31.077+0000] {standard_task_runner.py:60} INFO - Started process 202 to run task
[2025-03-05T22:19:31.081+0000] {standard_task_runner.py:87} INFO - Running: ['***', 'tasks', 'run', 'mercadolibre_técnica', 'email_alert_task', 'manual__2025-03-05T22:19:26.784773+00:00', '--job-id', '18', '--raw', '--subdir', 'DAGS_FOLDER/pl_mltest.py', '--cfg-path', '/tmp/tmpcfwjwrz_']
[2025-03-05T22:19:31.084+0000] {standard_task_runner.py:88} INFO - Job 18: Subtask email_alert_task
[2025-03-05T22:19:31.146+0000] {task_command.py:423} INFO - Running <TaskInstance: mercadolibre_técnica.email_alert_task manual__2025-03-05T22:19:26.784773+00:00 [running]> on host 95305a71ffa4
[2025-03-05T22:19:31.252+0000] {taskinstance.py:2480} INFO - Exporting env vars: AIRFLOW_CTX_DAG_OWNER='***' AIRFLOW_CTX_DAG_ID='mercadolibre_técnica' AIRFLOW_CTX_TASK_ID='email_alert_task' AIRFLOW_CTX_EXECUTION_DATE='2025-03-05T22:19:26.784773+00:00' AIRFLOW_CTX_TRY_NUMBER='1' AIRFLOW_CTX_DAG_RUN_ID='manual__2025-03-05T22:19:26.784773+00:00'
[2025-03-05T22:19:31.259+0000] {taskinstance.py:2698} ERROR - Task failed with exception
Traceback (most recent call last):
  File "/opt/airflow/dags/pl_mltest.py", line 122, in check_and_send_email
    cur.execute(
psycopg2.errors.FeatureNotSupported: cross-database references are not implemented: "public.mercadolibre.items"
LINE 3:             FROM public.mercadolibre.items
                         ^


During handling of the above exception, another exception occurred:

Traceback (most recent call last):
  File "/home/airflow/.local/lib/python3.8/site-packages/airflow/models/taskinstance.py", line 433, in _execute_task
    result = execute_callable(context=context, **execute_callable_kwargs)
  File "/home/airflow/.local/lib/python3.8/site-packages/airflow/operators/python.py", line 199, in execute
    return_value = self.execute_callable()
  File "/home/airflow/.local/lib/python3.8/site-packages/airflow/operators/python.py", line 216, in execute_callable
    return self.python_callable(*self.op_args, **self.op_kwargs)
  File "/opt/airflow/dags/pl_mltest.py", line 167, in check_and_send_email
    raise Exception(f"Error al enviar el email: {str(e)}")
Exception: Error al enviar el email: cross-database references are not implemented: "public.mercadolibre.items"
LINE 3:             FROM public.mercadolibre.items
                         ^

[2025-03-05T22:19:31.282+0000] {taskinstance.py:1138} INFO - Marking task as FAILED. dag_id=mercadolibre_técnica, task_id=email_alert_task, execution_date=20250305T221926, start_date=20250305T221931, end_date=20250305T221931
[2025-03-05T22:19:31.306+0000] {standard_task_runner.py:107} ERROR - Failed to execute job 18 for task email_alert_task (Error al enviar el email: cross-database references are not implemented: "public.mercadolibre.items"
LINE 3:             FROM public.mercadolibre.items
                         ^
; 202)
[2025-03-05T22:19:31.344+0000] {local_task_job_runner.py:234} INFO - Task exited with return code 1
[2025-03-05T22:19:31.368+0000] {taskinstance.py:3280} INFO - 0 downstream tasks scheduled from follow-on schedule check
