[2025-03-05T22:34:14.000+0000] {taskinstance.py:1956} INFO - Dependencies all met for dep_context=non-requeueable deps ti=<TaskInstance: mercadolibre_técnica.email_alert_task manual__2025-03-05T22:34:09.781839+00:00 [queued]>
[2025-03-05T22:34:14.010+0000] {taskinstance.py:1956} INFO - Dependencies all met for dep_context=requeueable deps ti=<TaskInstance: mercadolibre_técnica.email_alert_task manual__2025-03-05T22:34:09.781839+00:00 [queued]>
[2025-03-05T22:34:14.011+0000] {taskinstance.py:2170} INFO - Starting attempt 1 of 1
[2025-03-05T22:34:14.026+0000] {taskinstance.py:2191} INFO - Executing <Task(PythonOperator): email_alert_task> on 2025-03-05 22:34:09.781839+00:00
[2025-03-05T22:34:14.033+0000] {standard_task_runner.py:60} INFO - Started process 531 to run task
[2025-03-05T22:34:14.035+0000] {standard_task_runner.py:87} INFO - Running: ['***', 'tasks', 'run', 'mercadolibre_técnica', 'email_alert_task', 'manual__2025-03-05T22:34:09.781839+00:00', '--job-id', '30', '--raw', '--subdir', 'DAGS_FOLDER/pl_mltest.py', '--cfg-path', '/tmp/tmpro2mzkt4']
[2025-03-05T22:34:14.037+0000] {standard_task_runner.py:88} INFO - Job 30: Subtask email_alert_task
[2025-03-05T22:34:14.088+0000] {task_command.py:423} INFO - Running <TaskInstance: mercadolibre_técnica.email_alert_task manual__2025-03-05T22:34:09.781839+00:00 [running]> on host 95305a71ffa4
[2025-03-05T22:34:14.170+0000] {taskinstance.py:2480} INFO - Exporting env vars: AIRFLOW_CTX_DAG_OWNER='***' AIRFLOW_CTX_DAG_ID='mercadolibre_técnica' AIRFLOW_CTX_TASK_ID='email_alert_task' AIRFLOW_CTX_EXECUTION_DATE='2025-03-05T22:34:09.781839+00:00' AIRFLOW_CTX_TRY_NUMBER='1' AIRFLOW_CTX_DAG_RUN_ID='manual__2025-03-05T22:34:09.781839+00:00'
[2025-03-05T22:34:14.176+0000] {logging_mixin.py:188} INFO - Items con calor mayor a 7M: 50
[2025-03-05T22:34:17.827+0000] {taskinstance.py:2698} ERROR - Task failed with exception
Traceback (most recent call last):
  File "/opt/airflow/dags/pl_mltest.py", line 158, in check_and_send_email
    server.login(sender, password)
  File "/usr/local/lib/python3.8/smtplib.py", line 748, in login
    raise last_exception
  File "/usr/local/lib/python3.8/smtplib.py", line 737, in login
    (code, resp) = self.auth(
  File "/usr/local/lib/python3.8/smtplib.py", line 660, in auth
    raise SMTPAuthenticationError(code, resp)
smtplib.SMTPAuthenticationError: (534, b'5.7.9 Application-specific password required. For more information, go to\n5.7.9  https://support.google.com/mail/?p=InvalidSecondFactor 98e67ed59e1d1-2ff4e7a2b62sm1860480a91.32 - gsmtp')

During handling of the above exception, another exception occurred:

Traceback (most recent call last):
  File "/home/airflow/.local/lib/python3.8/site-packages/airflow/models/taskinstance.py", line 433, in _execute_task
    result = execute_callable(context=context, **execute_callable_kwargs)
  File "/home/airflow/.local/lib/python3.8/site-packages/airflow/operators/python.py", line 199, in execute
    return_value = self.execute_callable()
  File "/home/airflow/.local/lib/python3.8/site-packages/airflow/operators/python.py", line 216, in execute_callable
    return self.python_callable(*self.op_args, **self.op_kwargs)
  File "/opt/airflow/dags/pl_mltest.py", line 167, in check_and_send_email
    raise Exception(f"Error al enviar el email: {str(e)}")
Exception: Error al enviar el email: (534, b'5.7.9 Application-specific password required. For more information, go to\n5.7.9  https://support.google.com/mail/?p=InvalidSecondFactor 98e67ed59e1d1-2ff4e7a2b62sm1860480a91.32 - gsmtp')
[2025-03-05T22:34:17.871+0000] {taskinstance.py:1138} INFO - Marking task as FAILED. dag_id=mercadolibre_técnica, task_id=email_alert_task, execution_date=20250305T223409, start_date=20250305T223414, end_date=20250305T223417
[2025-03-05T22:34:17.891+0000] {standard_task_runner.py:107} ERROR - Failed to execute job 30 for task email_alert_task (Error al enviar el email: (534, b'5.7.9 Application-specific password required. For more information, go to\n5.7.9  https://support.google.com/mail/?p=InvalidSecondFactor 98e67ed59e1d1-2ff4e7a2b62sm1860480a91.32 - gsmtp'); 531)
[2025-03-05T22:34:17.918+0000] {local_task_job_runner.py:234} INFO - Task exited with return code 1
[2025-03-05T22:34:17.945+0000] {taskinstance.py:3280} INFO - 0 downstream tasks scheduled from follow-on schedule check
